[2025-09-25T10:16:19.574+0000] {taskinstance.py:1159} INFO - Dependencies all met for dep_context=non-requeueable deps ti=<TaskInstance: football_etl.create_views manual__2025-09-25T10:11:09.035724+00:00 [queued]>
[2025-09-25T10:16:19.577+0000] {taskinstance.py:1159} INFO - Dependencies all met for dep_context=requeueable deps ti=<TaskInstance: football_etl.create_views manual__2025-09-25T10:11:09.035724+00:00 [queued]>
[2025-09-25T10:16:19.577+0000] {taskinstance.py:1361} INFO - Starting attempt 1 of 2
[2025-09-25T10:16:19.582+0000] {taskinstance.py:1382} INFO - Executing <Task(PythonOperator): create_views> on 2025-09-25 10:11:09.035724+00:00
[2025-09-25T10:16:19.585+0000] {standard_task_runner.py:57} INFO - Started process 850 to run task
[2025-09-25T10:16:19.588+0000] {standard_task_runner.py:84} INFO - Running: ['airflow', 'tasks', 'run', 'football_etl', 'create_views', 'manual__2025-09-25T10:11:09.035724+00:00', '--job-id', '59', '--raw', '--subdir', 'DAGS_FOLDER/fetch _player_stats.py', '--cfg-path', '/tmp/tmphuveljfv']
[2025-09-25T10:16:19.588+0000] {standard_task_runner.py:85} INFO - Job 59: Subtask create_views
[2025-09-25T10:16:19.603+0000] {task_command.py:416} INFO - Running <TaskInstance: football_etl.create_views manual__2025-09-25T10:11:09.035724+00:00 [running]> on host 1afec62875aa
[2025-09-25T10:16:19.623+0000] {taskinstance.py:1662} INFO - Exporting env vars: AIRFLOW_CTX_DAG_OWNER='data_eng' AIRFLOW_CTX_DAG_ID='football_etl' AIRFLOW_CTX_TASK_ID='create_views' AIRFLOW_CTX_EXECUTION_DATE='2025-09-25T10:11:09.035724+00:00' AIRFLOW_CTX_TRY_NUMBER='1' AIRFLOW_CTX_DAG_RUN_ID='manual__2025-09-25T10:11:09.035724+00:00'
[2025-09-25T10:16:19.631+0000] {taskinstance.py:1937} ERROR - Task failed with exception
Traceback (most recent call last):
  File "/home/airflow/.local/lib/python3.8/site-packages/sqlalchemy/engine/base.py", line 1910, in _execute_context
    self.dialect.do_execute(
  File "/home/airflow/.local/lib/python3.8/site-packages/sqlalchemy/engine/default.py", line 736, in do_execute
    cursor.execute(statement, parameters)
psycopg2.errors.WrongObjectType: "team_aggregates" is not a view
HINT:  Use DROP TABLE to remove a table.


The above exception was the direct cause of the following exception:

Traceback (most recent call last):
  File "/home/airflow/.local/lib/python3.8/site-packages/airflow/operators/python.py", line 192, in execute
    return_value = self.execute_callable()
  File "/home/airflow/.local/lib/python3.8/site-packages/airflow/operators/python.py", line 209, in execute_callable
    return self.python_callable(*self.op_args, **self.op_kwargs)
  File "/opt/airflow/dags/create_view.py", line 60, in create_views
    conn.execute(q)
  File "/home/airflow/.local/lib/python3.8/site-packages/sqlalchemy/engine/base.py", line 1370, in execute
    return self._exec_driver_sql(
  File "/home/airflow/.local/lib/python3.8/site-packages/sqlalchemy/engine/base.py", line 1674, in _exec_driver_sql
    ret = self._execute_context(
  File "/home/airflow/.local/lib/python3.8/site-packages/sqlalchemy/engine/base.py", line 1953, in _execute_context
    self._handle_dbapi_exception(
  File "/home/airflow/.local/lib/python3.8/site-packages/sqlalchemy/engine/base.py", line 2134, in _handle_dbapi_exception
    util.raise_(
  File "/home/airflow/.local/lib/python3.8/site-packages/sqlalchemy/util/compat.py", line 211, in raise_
    raise exception
  File "/home/airflow/.local/lib/python3.8/site-packages/sqlalchemy/engine/base.py", line 1910, in _execute_context
    self.dialect.do_execute(
  File "/home/airflow/.local/lib/python3.8/site-packages/sqlalchemy/engine/default.py", line 736, in do_execute
    cursor.execute(statement, parameters)
sqlalchemy.exc.ProgrammingError: (psycopg2.errors.WrongObjectType) "team_aggregates" is not a view
HINT:  Use DROP TABLE to remove a table.

[SQL: 
        DROP VIEW IF EXISTS team_aggregates;
        CREATE TABLE team_aggregates AS
        SELECT 
            team_name,
            season_id,
            SUM(goals) AS total_goals,
            SUM(assists) AS total_assists,
            SUM(appearances) AS total_appearances,
            AVG(passes_accuracy_percent) AS avg_pass_accuracy,
            SUM(yellow_cards) AS total_yellow,
            SUM(red_cards) AS total_red,
            SUM(tackles) AS total_tackles,
            SUM(interceptions) AS total_interceptions,
            SUM(fouls) AS total_fouls
        FROM player_stats_gold
        GROUP BY team_name, season_id
        ORDER BY total_goals DESC;
        ]
(Background on this error at: https://sqlalche.me/e/14/f405)
[2025-09-25T10:16:19.634+0000] {taskinstance.py:1400} INFO - Marking task as UP_FOR_RETRY. dag_id=football_etl, task_id=create_views, execution_date=20250925T101109, start_date=20250925T101619, end_date=20250925T101619
[2025-09-25T10:16:19.638+0000] {standard_task_runner.py:104} ERROR - Failed to execute job 59 for task create_views ((psycopg2.errors.WrongObjectType) "team_aggregates" is not a view
HINT:  Use DROP TABLE to remove a table.

[SQL: 
        DROP VIEW IF EXISTS team_aggregates;
        CREATE TABLE team_aggregates AS
        SELECT 
            team_name,
            season_id,
            SUM(goals) AS total_goals,
            SUM(assists) AS total_assists,
            SUM(appearances) AS total_appearances,
            AVG(passes_accuracy_percent) AS avg_pass_accuracy,
            SUM(yellow_cards) AS total_yellow,
            SUM(red_cards) AS total_red,
            SUM(tackles) AS total_tackles,
            SUM(interceptions) AS total_interceptions,
            SUM(fouls) AS total_fouls
        FROM player_stats_gold
        GROUP BY team_name, season_id
        ORDER BY total_goals DESC;
        ]
(Background on this error at: https://sqlalche.me/e/14/f405); 850)
[2025-09-25T10:16:19.644+0000] {local_task_job_runner.py:228} INFO - Task exited with return code 1
[2025-09-25T10:16:19.650+0000] {taskinstance.py:2778} INFO - 0 downstream tasks scheduled from follow-on schedule check
